[2024-02-22T09:10:16.917+0000] {taskinstance.py:1956} INFO - Dependencies all met for dep_context=non-requeueable deps ti=<TaskInstance: welcome_dag.print_random_quote manual__2024-02-22T09:09:42.693835+00:00 [queued]>
[2024-02-22T09:10:16.945+0000] {taskinstance.py:1956} INFO - Dependencies all met for dep_context=requeueable deps ti=<TaskInstance: welcome_dag.print_random_quote manual__2024-02-22T09:09:42.693835+00:00 [queued]>
[2024-02-22T09:10:16.945+0000] {taskinstance.py:2170} INFO - Starting attempt 1 of 1
[2024-02-22T09:10:17.170+0000] {taskinstance.py:2191} INFO - Executing <Task(PythonOperator): print_random_quote> on 2024-02-22 09:09:42.693835+00:00
[2024-02-22T09:10:17.181+0000] {standard_task_runner.py:60} INFO - Started process 230 to run task
[2024-02-22T09:10:17.186+0000] {standard_task_runner.py:87} INFO - Running: ['airflow', 'tasks', 'run', 'welcome_dag', 'print_random_quote', 'manual__2024-02-22T09:09:42.693835+00:00', '--job-id', '22', '--raw', '--subdir', 'DAGS_FOLDER/welcome_dag.py', '--cfg-path', '/tmp/tmp88c0_oex']
[2024-02-22T09:10:17.191+0000] {standard_task_runner.py:88} INFO - Job 22: Subtask print_random_quote
[2024-02-22T09:10:17.784+0000] {task_command.py:423} INFO - Running <TaskInstance: welcome_dag.print_random_quote manual__2024-02-22T09:09:42.693835+00:00 [running]> on host 6281687bcd05
[2024-02-22T09:10:18.245+0000] {taskinstance.py:2480} INFO - Exporting env vars: AIRFLOW_CTX_DAG_OWNER='airflow' AIRFLOW_CTX_DAG_ID='welcome_dag' AIRFLOW_CTX_TASK_ID='print_random_quote' AIRFLOW_CTX_EXECUTION_DATE='2024-02-22T09:09:42.693835+00:00' AIRFLOW_CTX_TRY_NUMBER='1' AIRFLOW_CTX_DAG_RUN_ID='manual__2024-02-22T09:09:42.693835+00:00'
[2024-02-22T09:10:18.246+0000] {taskinstance.py:2698} ERROR - Task failed with exception
Traceback (most recent call last):
  File "/home/airflow/.local/lib/python3.8/site-packages/airflow/models/taskinstance.py", line 433, in _execute_task
    result = execute_callable(context=context, **execute_callable_kwargs)
  File "/home/airflow/.local/lib/python3.8/site-packages/airflow/operators/python.py", line 199, in execute
    return_value = self.execute_callable()
  File "/home/airflow/.local/lib/python3.8/site-packages/airflow/operators/python.py", line 216, in execute_callable
    return self.python_callable(*self.op_args, **self.op_kwargs)
  File "/opt/airflow/dags/welcome_dag.py", line 18, in print_random_quote
    quote_api= {var.value.get('quote_api')}
NameError: name 'var' is not defined
[2024-02-22T09:10:18.262+0000] {taskinstance.py:1138} INFO - Marking task as FAILED. dag_id=welcome_dag, task_id=print_random_quote, execution_date=20240222T090942, start_date=20240222T091016, end_date=20240222T091018
[2024-02-22T09:10:18.369+0000] {standard_task_runner.py:107} ERROR - Failed to execute job 22 for task print_random_quote (name 'var' is not defined; 230)
[2024-02-22T09:10:18.408+0000] {local_task_job_runner.py:234} INFO - Task exited with return code 1
[2024-02-22T09:10:18.434+0000] {taskinstance.py:3280} INFO - 0 downstream tasks scheduled from follow-on schedule check
